Workbook

Sheet Cover Page
B2: ESKAY CREEK
B3: Net Asset Value Model
B4: Skeena Gold & Silver | TSX: SKE | NYSE: SKE
B6: Last Updated | C6: March 13, 2026 | D6: ← Update this date when refreshing inputs
B7: Prepared By | C7: Kyle Tsuji
B8: Model Version | C8: 1
B9: Comps Last Updated | C9: =Comps!C5 -> 46094 | D9: ← Linked from Comps sheet
B10: INPUTS TO UPDATE PERIODICALLY | F10: NAV SUMMARY
B11: Input | C11: Current Value | D11: Source / Where to Find | F11: Active Scenario | G11: ='NAV Model'!C14 -> Base
B12: MARKET DATA | F12: NAV (US$ mm) | G12: ='NAV Model'!C6 -> 6383.9423
B13: Current Share Price (C$) | C13: ='NAV Model'!C8*'NAV Model'!$C$24 -> 43.1002 | D13: Yahoo Finance / Bloomberg | F13: NAV per Share (C$) | G13: ='NAV Model'!C7*'NAV Model'!$C$24 -> 72.102234
B14: Shares Outstanding (mm) | C14: ='NAV Model'!C32 -> 121.3 | D14: Latest quarterly filing (MD&A) | F14: Share Price (C$) | G14: =C13 -> 43.1002
B15: USD/CAD Exchange Rate | C15: ='NAV Model'!C24 -> 1.37 | D15: Bank of Canada / xe.com | F15: P/NAV Multiple | G15: ='NAV Model'!C9 -> 0.59776511
F16: Mine Life (Years) | G16: ='NAV Model'!C10 -> 12
B17: BALANCE SHEET DATA | F17: LOM Gold Production (koz) | G17: ='NAV Model'!C11 -> 2723.6147
B18: Cash & Equivalents (C$ 000s) | C18: ='Balance Sheet'!B7 -> 96941 | D18: Quarterly financial statements | F18: LT Gold Price (US$/oz) | G18: ='NAV Model'!C18 -> 3150
B19: Lease Liabilities — Current (C$ 000s) | C19: ='Balance Sheet'!B20 -> 6303 | D19: Quarterly financial statements | F19: Discount Rate | G19: ='NAV Model'!C25 -> 0.05
B20: Lease Liabilities — Non-current (C$ 000s) | C20: ='Balance Sheet'!B24 -> 7230 | D20: Quarterly financial statements
B21: Gold Stream Derivative (C$ 000s) | C21: ='Balance Sheet'!B25 -> 63886 | D21: Quarterly financial statements | F21: Valuation Summary
B22: → Net Debt (negative = net cash) (US$ mm) | C22: =(SUM(C19:C21)-C18)/1000/'NAV Model'!C24 -> -14.249635 | D22: Auto-calculated from above | F22: Valuation Method | G22: Implied Value (C$) | H22: Weight
F23: Comps: P/NAV | G23: =Comps!O27 -> 59.844854 | H23: 0.4
B24: COMMODITY PRICE SCENARIOS | F24: Comps: EV/Reserves | G24: =Comps!P27 -> 50.50882 | H24: 0.2
B25: Active Scenario | C25: ='NAV Model'!C14 -> Base | D25: Change via dropdown on NAV Model!B15 | F25: Comps: EV/Resources | G25: =Comps!Q27 -> 38.222004 | H25: 0.1
B26: Gold & Silver Price Assumptions | C26: See table → | D26: Edit on Economic Assumptions (E4:I17) | F26: Precedents: P/NAV | G26: =PTA!J24 -> 79.312457 | H26: 0.1
F27: Analyst Targets | G27: ='Broker Summary'!D12 -> 52.2 | H27: 0.2
B28: MODEL ASSUMPTIONS (change less frequently) | F28: Blended Valuation (C$) | G28: =SUMPRODUCT(G23:G27,H23:H27) -> 56.233152
B29: Discount Rate (WACC) | C29: ='NAV Model'!C25 -> 0.05 | D29: Technical report | F29: Current Share Price (C$) | G29: =C13 -> 43.1002
B30: Royalty Rate (NSR) | C30: ='NAV Model'!C26 -> 0.02 | D30: Technical report / royalty agreements | F30: Implied Upside | G30: =G28/G29-1 -> 0.30470744
B31: Corporate Tax Rate | C31: ='NAV Model'!C27 -> 0.27 | D31: Technical report / BC mining tax + federal rate
B32: Depreciation Method | C32: ='NAV Model'!C37 -> Units-of-Production | D32: Units-of-Production recommended
B33: Depreciable Asset Base (US$ mm) | C33: ='NAV Model'!C34 -> 520.43796 | D33: Pre-prod capex from technical report
B34: Closure Cost (US$ mm) | C34: ='NAV Model'!C39 -> 127.59124 | D34: Technical report / updated estimates | F34: Valuation Summary
F35: Valuation Method | G35: Low (C$) | H35: Difference | I35: High (C$)
B36: PERIODIC UPDATE CHECKLIST | F36: Comps: P/NAV | G36: =Comps!O29 -> 23.793737 | H36: =I36-G36 -> 56.960765 | I36: =Comps!O28 -> 80.754502
B37: Frequency | C37: Action | D37: Location | F37: Comps: EV/Reserves | G37: =Comps!P29 -> 18.510832 | H37: =I37-G37 -> 56.79761 | I37: =Comps!P28 -> 75.308441
B38: Daily / Weekly | C38: Update share price | D38: NAV Model → B8 | F38: Comps: EV/Resources | G38: =Comps!Q29 -> 15.783179 | H38: =I38-G38 -> 27.850305 | I38: =Comps!Q28 -> 43.633484
B39: Daily / Weekly | C39: Update USD/CAD exchange rate | D39: NAV Model → B25 | F39: Precedents: P/NAV | G39: =PTA!J26 -> 69.218145 | H39: =I39-G39 -> 38.935206 | I39: =PTA!J25 -> 108.15335
B40: Quarterly | C40: Update Balance Sheet (cash, leases, Gold Stream) | D40: Balance Sheet → Column B | F40: 52-Week Range | G40: 12.15 | H40: =I40-G40 -> 40.85 | I40: 53
B41: Quarterly | C41: Update shares outstanding (check for dilution) | D41: NAV Model → B29 | F41: Analyst Targets | G41: ='Broker Summary'!D9 -> 49 | H41: =I41-G41 -> 11 | I41: ='Broker Summary'!D5 -> 60
B42: As Needed | C42: Refresh commodity price scenarios (Bear/Base/Bull) | D42: Economic Assumptions → E4:I17
...

Sheet Economic Assumptions
A1: ECONOMIC & FISCAL ASSUMPTIONS | F1: COMMODITY PRICE SCENARIOS
A2: Source: Eskay Creek NI 43-101 Updated Feasibility Study, December 22, 2023 | F2: Toggle scenario on NAV Model sheet (cell B14)
A3: Technical Report Link | F3: Prices updated as of: | G3: ='Cover Page'!C6 -> March 13, 2026
A5: BASE CASE ASSUMPTIONS | F5: GOLD PRICES (US$/oz) | H5: Bear | I5: Base | J5: Bull
A6: Parameter | B6: Units | C6: Value | D6: Relevance to NAV Model | F6: Year | G6: Period | H6: US$/oz | I6: US$/oz | J6: US$/oz
A7: Gold Price | B7: US$/oz | C7: =I10 -> 3150 | D7: Drives gross gold revenue; key sensitivity variable in NAV | F7: 2027 | G7: Near-term | H7: 4075 | I7: =AVERAGE(H7,J7) -> 5287.5 | J7: 6500
A8: Silver Price | B8: US$/oz | C8: =I17 -> 42 | D8: Drives silver by-product credits, reducing net cash costs | F8: 2028 | G8: Near-term | H8: 3675 | I8: =AVERAGE(H8,J8) -> 4837.5 | J8: 6000
A9: Exchange Rate (US$/C$) | B9: US$/C$ | C9: 0.74 | D9: Converts C$ costs to US$ for revenue/cost reconciliation | F9: 2029 | G9: Near-term | H9: 3425 | I9: =AVERAGE(H9,J9) -> 4462.5 | J9: 5500
A10: Discount Rate | B10: % | C10: 0.05 | D10: Taken as the project discount rate (5%) | F10: 2030+ | G10: Long-term | H10: 3000 | I10: =AVERAGE(H10,J10) -> 3150 | J10: 3300
A11: Royalty (NSR) | B11: % | C11: 0.02 | D11: Deducted from gross revenue to arrive at net revenue
A12: Strip Ratio (waste:ore) | B12: x | C12: 7.98:1 | D12: Impacts mining cost per tonne; higher ratio = more waste moved | F12: SILVER PRICES (US$/oz) | H12: Bear | I12: Base | J12: Bull
A13: Grams per Troy Ounce | B13: g/oz | C13: 31.1035 | D13: Converts grade (g/t) × tonnes to troy ounces for contained metal calculations | F13: Year | G13: Period | H13: US$/oz | I13: US$/oz | J13: US$/oz
A14: PRODUCTION & METALLURGY | F14: 2027 | G14: Near-term | H14: 49.5 | I14: 80 | J14: 120
A15: Parameter | B15: Units | C15: Value | D15: Relevance to NAV Model | F15: 2028 | G15: Near-term | H15: 45.25 | I15: 65 | J15: 105
A16: Processing Life | B16: years | C16: 12 | D16: Determines number of years of cash flows to discount | F16: 2029 | G16: Near-term | H16: 40.75 | I16: 55 | J16: 95
A17: Throughput (Years 1–5) | B17: Mtpa | C17: 3 | D17: Sets annual ore tonnage in early years → drives revenue timing | F17: 2030+ | G17: Long-term | H17: 33 | I17: 42 | J17: 70
A18: Throughput (Years 6–12) | B18: Mtpa | C18: 3.5 | D18: Sets annual ore tonnage in later years; higher throughput boosts output
A19: Avg Diluted Au Grade | B19: g/t | C19: 2.6 | D19: Multiplied by throughput and recovery to calculate gold ounces produced | F19: SOURCES
A20: Avg Diluted Ag Grade | B20: g/t | C20: 68.7 | D20: Multiplied by throughput and recovery to calculate silver ounces produced | F20: Bear | G20: BMO Capital Markets, as of December 15, 2025
A21: Gold Recovery (to concentrate) | B21: % | C21: 0.83 | D21: % of gold in ore recovered to concentrate; directly scales gold output | F21: Base | G21: Average of the two estimates (Au), and NBC Ag estimates as of February 2026
A22: Silver Recovery (to concentrate) | B22: % | C22: 0.91 | D22: % of silver in ore recovered to concentrate; scales silver by-product credit | F22: Bull | G22: CIBC Capital Markets, as of February 2, 2026
A23: LOM Gold Production | B23: koz | C23: 2769 | D23: Total gold ounces over mine life; basis for LOM revenue calculation
A24: LOM Silver Production | B24: koz | C24: 80052 | D24: Total silver ounces over mine life; drives cumulative by-product credits
A25: LOM AuEq Production | B25: koz | C25: 3891 | D25: Gold-equivalent total production; used for co-product cost metrics
A26: LOM Avg Annual Au Production | B26: koz/yr | C26: 228 | D26: Annual gold output benchmark; revenue run-rate indicator
A27: LOM average annual silver production (koz) | B27: koz/yr | C27: 6583 | D27: Annual silver output; feeds annual by-product credit calculation
A28: LOM Avg Annual AuEq Production | B28: koz/yr | C28: 320 | D28: Annual AuEq output; used to derive co-product cost per ounce
A30: CAPITAL EXPENDITURES
A31: Parameter | B31: Units | C31: Value | D31: Relevance to NAV Model
A32: Pre-Production Capex | B32: C$M | C32: 713 | D32: Upfront build cost; deducted from NAV as PV of remaining capex
A33: Expansion Capex | B33: C$M | C33: 9 | D33: One-time expansion spend; adds to total capex in year incurred
A34: Sustaining Capex | B34: C$M | C34: 561 | D34: Annual maintenance capex; included in AISC and deducted from FCF
A35: Closure Costs | B35: C$M | C35: 174.8 | D35: End-of-life reclamation cost; deducted from final-year FCF
A36: Initial Working Capital | B36: C$M | C36: 43.3 | D36: Pre-production ore stockpile; deducted from NAV as PV of working capital outflow

Sheet Models ->

Sheet NAV Model
B1: ESKAY CREEK — NAV MODEL
B2: Skeena Gold & Silver | Net Asset Value Analysis
B3: All figures in USD millions unless otherwise stated
A5: * | B5: KEY OUTPUTS
B6: NAV (US$ mm) | C6: =Q116 -> 6383.9423
B7: NAV per Share (US$) | C7: =Q117 -> 52.629368
B8: Current Share Price (US$) | C8: 31.46
B9: P/NAV Multiple | C9: =IF(C7=0,0,C8/C7) -> 0.59776511
B10: Mine Life (Years) | C10: ='Economic Assumptions'!C16 -> 12
B11: Total LOM Production (koz) | C11: =SUM(F62:Q62)/1000 -> 2723.6147
A13: * | B13: KEY ASSUMPTIONS
B14: ▶ Price Scenario | C14: Base
B15: 2027 Gold Price (US$/oz) | C15: =INDEX('Economic Assumptions'!H7:J7,MATCH(C14,{"Bear","Base","Bull"},0)) -> 5287.5
B16: 2028 Gold Price (US$/oz) | C16: =INDEX('Economic Assumptions'!H8:J8,MATCH(C14,{"Bear","Base","Bull"},0)) -> 4837.5
B17: 2029 Gold Price (US$/oz) | C17: =INDEX('Economic Assumptions'!H9:J9,MATCH(C14,{"Bear","Base","Bull"},0)) -> 4462.5
B18: LT Gold Price (US$/oz) | C18: =INDEX('Economic Assumptions'!H10:J10,MATCH(C14,{"Bear","Base","Bull"},0)) -> 3150
B19: 2027 Silver Price (US$/oz) | C19: =INDEX('Economic Assumptions'!H14:J14,MATCH(C14,{"Bear","Base","Bull"},0)) -> 80
B20: 2028 Silver Price (US$/oz) | C20: =INDEX('Economic Assumptions'!H15:J15,MATCH(C14,{"Bear","Base","Bull"},0)) -> 65
B21: 2029 Silver Price (US$/oz) | C21: =INDEX('Economic Assumptions'!H16:J16,MATCH(C14,{"Bear","Base","Bull"},0)) -> 55
B22: LT Silver Price (US$/oz) | C22: =INDEX('Economic Assumptions'!H17:J17,MATCH(C14,{"Bear","Base","Bull"},0)) -> 42
B23: Silver:Gold Ratio | C23: =IFERROR(C18/C22,0) -> 75
B24: USD/CAD Exchange Rate | C24: 1.37
B25: Discount Rate (WACC) | C25: ='Economic Assumptions'!C10 -> 0.05
B26: Royalty Rate (%) | C26: ='Economic Assumptions'!C11 -> 0.02
B27: Corporate Tax Rate (%) | C27: 0.27
B28: → Federal Income Tax | C28: 0.15
B29: → Provincial Income Tax (BC) | C29: 0.12
B30: BC Mineral Tax — NCP (net current proceeds) Rate (%) | C30: 0.02
B31: BC Mineral Tax — NRT (net revenue tax) Rate (%) | C31: 0.13
B32: Shares Outstanding (mm) | C32: 121.3
B33: Net Debt (negative = net cash) (US$ mm) | C33: =(61.7-108.2)/'Cover Page'!C15 -> -33.941606
B34: Depreciable Asset Base (US$ mm) | C34: ='Economic Assumptions'!C32/C24 -> 520.43796
B35: Pre-Production Capex (US$ mm) | C35: =C34 -> 520.43796
B36: Less: Already Spent (US$ mm) | C36: =437.742/'Cover Page'!C15 -> 319.51971
B37: Depreciation Method | C37: Units-of-Production
B38: Salvage Value (US$ mm) | C38: 0
B39: Closure Cost (US$ mm) | C39: ='Economic Assumptions'!C35/C24 -> 127.59124
B40: Initial Working Capital Adj. (US$ mm) | C40: ='Economic Assumptions'!C36/C24 -> 31.605839
B41: Additional M&I Conversion | C41: No
B42: Gold Stream Scenario | C42: None
...

Sheet Comps
B2: SELECTED PUBLIC MARKET COMPARABLES ¹
B4: DATA FRESHNESS
B5: Comps Last Updated | C5: 46094 | D5: ← Update this date when refreshing comps
B6: Current Share Price | C6: ='NAV Model'!C8*'NAV Model'!$C$24 -> 43.1002
B8: Description | N8: Valuation
B9: Company | C9: Ticker | D9: Domicile | E9: Share Price (LC) | F9: Market Cap ($mm LC) | G9: EV ($mm LC) | H9: Reserves (kozAuEq) | I9: Resources (kozAuEq) | J9: Shares Outstanding (mm) | K9: NAV | L9: EBITDA ($mm LC) | N9: NAV | P9: EV/Materials (LC/kozAuEq) | R9: EV/EBITDA
L10: 2026E | M10: 2027E | N10: /share (LC) | O10: P/NAV | P10: EV/Reserves | Q10: EV/Resources | R10: 2026E | S10: 2027E
A11: Development | B11: Bellevue Gold | C11: BGL | D11: Australia | E11: 1.615 | F11: 2391.4 | G11: 2566 | H11: =1.29*1000 -> 1290 | I11: =3.1*1000 -> 3100 | J11: 1480.7 | K11: =F11/0.86 -> 2780.6977 | L11: 402.9 | M11: 591.1 | N11: =K11/J11 -> 1.8779616 | O11: =F11/K11 -> 0.86 | P11: =$G11/H11 -> 1.9891473 | Q11: =$G11/I11 -> 0.82774194 | R11: =$G11/L11 -> 6.368826 | S11: =$G11/M11 -> 4.341059 | U11: Potential comps
A12: Stage | B12: Rupert Resources | C12: RUP | D12: Canada | E12: 7.52 | F12: 1770.2 | G12: 1684.4 | H12: =3.5*1000 -> 3500 | I12: =5*1000 -> 5000 | J12: 235.4 | K12: =F12/0.33 -> 5364.2424 | L12: N/A | M12: N/A | N12: =K12/J12 -> 22.787776 | O12: =F12/K12 -> 0.33 | P12: =$G12/H12 -> 0.48125714 | Q12: =$G12/I12 -> 0.33688 | R12: N/A | S12: N/A | U12: Bellevue Gold | W12: yes
B13: G Mining Ventures | C13: GMIN | D13: Canada | E13: 51.48 | F13: 8648.2 | G13: 8671.2 | H13: 6516 | I13: 9165 | J13: 228.2 | K13: =F13/0.8 -> 10810.25 | L13: 432.8 | M13: 595.2 | N13: =K13/J13 -> 47.371823 | O13: =F13/K13 -> 0.8 | P13: =$G13/H13 -> 1.3307551 | Q13: =$G13/I13 -> 0.94612111 | R13: =$G13/L13 -> 20.03512 | S13: =$G13/M13 -> 14.568548 | U13: G Mining Ventures | W13: maybe - BRA jurisdiciton but similar stage
A14: Single-Asset | B14: Lundin Gold | C14: LUG | D14: Canada | E14: 112.18 | F14: 27098.3 | G14: 19339.7 | H14: 5845 | I14: 7480 | J14: 241.7 | K14: =F14/1.1 -> 24634.818 | L14: 1792.5 | M14: 1868.7 | N14: =K14/J14 -> 101.92312 | O14: =F14/K14 -> 1.1 | P14: Ignored since materially higher post-production | R14: =$G14/L14 -> 10.789233 | S14: =$G14/M14 -> 10.34928
A15: Producers | B15: K92 Mining | C15: KNT | D15: Canada | E15: 27.67 | F15: 4967.7 | G15: 4842 | H15: =1.69*1000 -> 1690 | I15: =2600 -> 2600 | J15: 243.9 | K15: =F15/0.56 -> 8870.8929 | L15: 664.7 | M15: 994 | N15: =K15/J15 -> 36.371024 | O15: =F15/K15 -> 0.56 | R15: =$G15/L15 -> 7.2844892 | S15: =$G15/M15 -> 4.8712274
B16: Wesdome Gold | C16: WDO | D16: Canada | E16: 23.42 | F16: 3521.9 | G16: 3237.2 | H16: 1188 | I16: =H16+386 -> 1574 | J16: 150.4 | K16: =F16/1.12 -> 3144.5536 | L16: 601 | M16: 936 | N16: =K16/J16 -> 20.907936 | O16: =F16/K16 -> 1.12 | R16: =$G16/L16 -> 5.3863561 | S16: =$G16/M16 -> 3.458547 | U16: Lundin Gold | W16: Similar mine but alr producing in Ecuador
U17: K92 Mining | W17: Similar mine but alr producing in PNG
B18: Skeena Resources | C18: SKE | D18: Canada | E18: =C6 -> 43.1002 | F18: =E18*J18 -> 5228.0543 | G18: =F18+'NAV Model'!C33*'NAV Model'!$C$24 -> 5181.5543 | H18: ='Reserve & Resource'!F16 -> 4569 | I18: ='Reserve & Resource'!F7 -> 5545 | J18: ='NAV Model'!C32 -> 121.3 | K18: ='Cover Page'!G12*'NAV Model'!$C$24 -> 8746.001 | L18: N/A | M18: 687.9 | N18: =K18/J18 -> 72.102234 | O18: =F18/K18 -> 0.59776511 | P18: =$G18/H18 -> 1.1340675 | Q18: =$G18/I18 -> 0.93445523 | R18: N/A | S18: =$G18/M18 -> 7.5324237 | U18: Wesdome Gold | W18: 2 mines in CAD both producing
B19: Junior Gold | U19: Rupert Resources | W19: yes
B20: Mean | O20: =AVERAGE(O11:O16) -> 0.795 | P20: =AVERAGE(P11:P16) -> 1.2670532 | Q20: =AVERAGE(Q11:Q16) -> 0.70358102 | R20: =AVERAGE(R11:R16) -> 9.9728049 | S20: =AVERAGE(S11:S16) -> 7.5177324
B21: Median | O21: =MEDIAN(O11:O16) -> 0.83 | P21: =MEDIAN(P11:P16) -> 1.3307551 | Q21: =MEDIAN(Q11:Q16) -> 0.82774194 | R21: =MEDIAN(R11:R16) -> 7.2844892 | S21: =MEDIAN(S11:S16) -> 4.8712274
B22: High | O22: =MAX(O11:O16) -> 1.12 | P22: =MAX(P11:P16) -> 1.9891473 | Q22: =MAX(Q11:Q16) -> 0.94612111 | R22: =MAX(R11:R16) -> 20.03512 | S22: =MAX(S11:S16) -> 14.568548
B23: Low | O23: =MIN(O11:O16) -> 0.33 | P23: =MIN(P11:P16) -> 0.48125714 | Q23: =MIN(Q11:Q16) -> 0.33688 | R23: =MIN(R11:R16) -> 5.3863561 | S23: =MIN(S11:S16) -> 3.458547
B25: Implied Valuation (C$)
B26: Mean | O26: =O20*$K$18/$J$18 -> 57.321276 | P26: =(P20*$H$18-($G$18-$F$18))/$J$18 -> 48.109364 | Q26: =(Q20*$I$18-($G$18-$F$18))/$J$18 -> 32.546222 | R26: N/A | S26: =(S20*$M$18-($G$18-$F$18))/$J$18 -> 43.016885
B27: Median | O27: =O21*$K$18/$J$18 -> 59.844854 | P27: =(P21*$H$18-($G$18-$F$18))/$J$18 -> 50.50882 | Q27: =(Q21*$I$18-($G$18-$F$18))/$J$18 -> 38.222004 | R27: N/A | S27: =(S21*$M$18-($G$18-$F$18))/$J$18 -> 28.008387
B28: High | O28: =O22*$K$18/$J$18 -> 80.754502 | P28: =(P22*$H$18-($G$18-$F$18))/$J$18 -> 75.308441 | Q28: =(Q22*$I$18-($G$18-$F$18))/$J$18 -> 43.633484 | R28: N/A | S28: =(S22*$M$18-($G$18-$F$18))/$J$18 -> 83.00251
B29: Low | O29: =O23*$K$18/$J$18 -> 23.793737 | P29: =(P23*$H$18-($G$18-$F$18))/$J$18 -> 18.510832 | Q29: =(Q23*$I$18-($G$18-$F$18))/$J$18 -> 15.783179 | R29: N/A | S29: =(S23*$M$18-($G$18-$F$18))/$J$18 -> 19.996987
A31: * | B31: Implied Upside
B32: Mean | O32: =O26/$C$6-1 -> 0.32995383 | P32: =P26/$C$6-1 -> 0.11622137 | Q32: =Q26/$C$6-1 -> -0.24487074 | R32: N/A | S32: =S26/$C$6-1 -> -0.0019330586
B33: Median | O33: =O27/$C$6-1 -> 0.38850525 | P33: =P27/$C$6-1 -> 0.17189294 | Q33: =Q27/$C$6-1 -> -0.11318269 | R33: N/A | S33: =S27/$C$6-1 -> -0.35015646
B34: High | O34: =O28/$C$6-1 -> 0.87364564 | P34: =P28/$C$6-1 -> 0.74728752 | Q34: =Q28/$C$6-1 -> 0.012373114 | R34: N/A | S34: =S28/$C$6-1 -> 0.92580336
B35: Low | O35: =O29/$C$6-1 -> -0.44794369 | P35: =P29/$C$6-1 -> -0.57051634 | Q35: =Q29/$C$6-1 -> -0.63380265 | R35: N/A | S35: =S29/$C$6-1 -> -0.53603494
B37: ¹ The peer set was selected to reflect a balanced mix of development-stage peers and high-grade single-asset producers, providing both a current trading benchmark and a forward-looking re-rating reference as Skeena transitions to production.
G41: Link for debt breakdown
G42: https://www.torys.com/work/2024/06/75631740-9d8c-4327-adea-365cb4b93607

Sheet PTA
B2: PRECEDENT TRANSACTIONS ANALYSIS
B4: DATA FRESHNESS
B5: Precedents Last Updated | D5: 46088 | E5: ← Update this date when refreshing comps
B6: Current Share Price | D6: ='NAV Model'!C8*'NAV Model'!$C$24 -> 43.1002
B8: Description | I8: Valuation
B9: Target Company | C9: Acquirer | D9: Transaction Date | E9: Domicile | F9: Share Price (LC) | G9: Market Cap ($mm LC) | H9: EV ($mm LC) | I9: Premium to Last Close (%) | J9: P/NAV
B10: Gold Road Resources | C10: Gold Fields Limited | D10: Sep-26-25 | E10: Australia | F10: 5.58 | G10: 7525 | H10: 6852.6 | I10: 0.14 | J10: 1.1
B11: Osisko Mining | C11: Gold Fields Limited | D11: 45590 | E11: Canada | F11: 6.73 | G11: 7687.9 | H11: 7649.2 | I11: 0.55 | J11: 0.96
B12: De Grey Mining | C12: Northern Star Resources | D12: 45782 | E12: Australia | F12: 8.48 | G12: 6421.5 | H12: 5662.8 | I12: 0.41 | J12: 1.1
B13: Pretium Resources | C13: Newcrest Mining | D13: 44629 | E13: Australia | F13: 1.615 | G13: 2391.4 | H13: 2566 | I13: 0.24 | J13: 1.5
B15: Skeena Resources | E15: Canada | F15: =Comps!E18 -> 43.1002 | G15: =Comps!F18 -> 5228.0543 | H15: =Comps!G18 -> 5181.5543 | I15: N/A | J15: =G15/('Cover Page'!G12*'NAV Model'!$C$24) -> 0.59776511
B16: Junior Gold
B17: Mean | I17: =AVERAGE(I10:I13) -> 0.335 | J17: =AVERAGE(J10:J13) -> 1.165
B18: Median | I18: =MEDIAN(I10:I13) -> 0.325 | J18: =MEDIAN(J10:J13) -> 1.1
B19: High | I19: =MAX(I10:I13) -> 0.55 | J19: =MAX(J10:J13) -> 1.5
B20: Low | I20: =MIN(I10:I13) -> 0.14 | J20: =MIN(J10:J13) -> 0.96
B22: Implied Valuation (C$)
B23: Mean | I23: =(I17+1)*$F$15 -> 57.538767 | J23: =J17*'Cover Page'!G13 -> 83.999102
B24: Median | I24: =(I18+1)*$F$15 -> 57.107765 | J24: =J18*'Cover Page'!G13 -> 79.312457
B25: High | I25: =(I19+1)*$F$15 -> 66.80531 | J25: =J19*'Cover Page'!G13 -> 108.15335
B26: Low | I26: =(I20+1)*$F$15 -> 49.134228 | J26: =J20*'Cover Page'!G13 -> 69.218145
A28: * | B28: Implied Upside
B29: Mean | I29: =I23/$D$6-1 -> 0.335 | J29: =J23/$D$6-1 -> 0.94892605
B30: Median | I30: =I24/$D$6-1 -> 0.325 | J30: =J24/$D$6-1 -> 0.84018768
B31: High | I31: =I25/$D$6-1 -> 0.55 | J31: =J25/$D$6-1 -> 1.5093468
B32: Low | I32: =I26/$D$6-1 -> 0.14 | J32: =J26/$D$6-1 -> 0.60598198

Sheet Broker Summary
B2: Broker Summary
C4: Bank | D4: Price Target (C$)
C5: UBS | D5: 60
C6: CIBC | D6: 58
C7: Our Target | D7: ='Cover Page'!G28 -> 56.233152
C8: Raymond James | D8: 50
C9: TD | D9: 49
C10: Scotiabank | D10: 44
C12: Analyst Target | D12: =AVERAGE(D8:D10,D5:D6) -> 52.2

Sheet Thesis Support ->

Sheet Thesis 2
B1: EXPANSION THESIS — PRODUCTION UPLIFT
B2: Incremental Gold & Silver Production from M&I Resource Expansion
B3: Compares base NAV Model production to expanded scenario across LOM
B5: GOLD PRODUCTION (oz)
B6: Scenario | C6: Units | D6: ='NAV Model'!F56 -> 2027 | E6: ='NAV Model'!G56 -> 2028 | F6: ='NAV Model'!H56 -> 2029 | G6: ='NAV Model'!I56 -> 2030 | H6: ='NAV Model'!J56 -> 2031 | I6: ='NAV Model'!K56 -> 2032 | J6: ='NAV Model'!L56 -> 2033 | K6: ='NAV Model'!M56 -> 2034 | ... O6: ='NAV Model'!Q56 -> 2038 | P6: LOM Total | Q6: LOM Avg
B7: Base Model | C7: oz | D7: 394939.48 | E7: 273095.31 | F7: 312215.67 | G7: 288199.08 | H7: 312215.67 | I7: 309093.51 | J7: 177455.91 | K7: 242834.41 | L7: 158776.34 | M7: 112397.64 | N7: 74718.279 | O7: 67673.413 | P7: =SUM(D7:O7) -> 2723614.7 | Q7: =AVERAGE(D7:O7) -> 226967.89
B8: Expansion | C8: oz | D8: 447311.54 | E8: 308708.32 | F8: 353065.88 | G8: 325906.97 | H8: 353065.88 | I8: 343659.08 | J8: 197357.3 | K8: 270067.88 | L8: 176582.85 | M8: 124966.94 | N8: 83097.81 | O8: 76052.944 | P8: =SUM(D8:O8) -> 3059843.4 | Q8: =AVERAGE(D8:O8) -> 254986.95
B9: Incremental Uplift | C9: oz | D9: =D8-D7 -> 52372.068 | E9: =E8-E7 -> 35613.006 | F9: =F8-F7 -> 40850.213 | G9: =G8-G7 -> 37707.889 | H9: =H8-H7 -> 40850.213 | I9: =I8-I7 -> 34565.565 | J9: =J8-J7 -> 19901.386 | K9: =K8-K7 -> 27233.475 | ... O9: =O8-O7 -> 8379.5308 | P9: =SUM(D9:O9) -> 336228.67 | Q9: =AVERAGE(D9:O9) -> 28019.056 | R9: =Q9/Q7 -> 0.12344943
B11: SILVER PRODUCTION (oz)
B12: Scenario | C12: Units | D12: =D6 -> 2027 | E12: =E6 -> 2028 | F12: =F6 -> 2029 | G12: =G6 -> 2030 | H12: =H6 -> 2031 | I12: =I6 -> 2032 | J12: =J6 -> 2033 | K12: =K6 -> 2034 | ... O12: =O6 -> 2038 | P12: LOM Total | Q12: LOM Avg
B13: Base Model | C13: oz | D13: 7915348.4 | E13: 7573507.8 | F13: 10111274 | G13: 8891250.2 | H13: 12955069 | I13: 6469635.3 | J13: 4188162.1 | K13: 9789444.9 | L13: 6215683.1 | M13: 2423545.9 | N13: 1402880.7 | O13: 1057295.2 | P13: =SUM(D13:O13) -> 78993097 | Q13: =AVERAGE(D13:O13) -> 6582758
B14: Expansion | C14: oz | D14: 8964985.6 | E14: 8561131.4 | F14: 11434230 | G14: 10054579 | H14: 14650107 | I14: 7193127 | J14: 4657857.5 | K14: 10887315 | L14: 6912761.7 | M14: 2694568.2 | N14: 1560211.4 | O14: 1188212.7 | P14: =SUM(D14:O14) -> 88759086 | Q14: =AVERAGE(D14:O14) -> 7396590.5
B15: Incremental Uplift | C15: oz | D15: =D14-D13 -> 1049637.2 | E15: =E14-E13 -> 987623.62 | F15: =F14-F13 -> 1322956.3 | G15: =G14-G13 -> 1163328.8 | H15: =H14-H13 -> 1695037.7 | I15: =I14-I13 -> 723491.72 | J15: =J14-J13 -> 469695.42 | K15: =K14-K13 -> 1097870 | ... O15: =O14-O13 -> 130917.55 | P15: =SUM(D15:O15) -> 9765989.8 | Q15: =AVERAGE(D15:O15) -> 813832.49 | R15: =Q15/Q13 -> 0.12363093
B17: Discounted FCF (US$ mm)
B18: Scenario | C18: Units | D18: =D12 -> 2027 | E18: =E12 -> 2028 | F18: =F12 -> 2029 | G18: =G12 -> 2030 | H18: =H12 -> 2031 | I18: =I12 -> 2032 | J18: =J12 -> 2033 | K18: =K12 -> 2034 | ... O18: =O12 -> 2038 | P18: LOM Total | Q18: LOM Avg
B19: Discounted FCF - Base | C19: US$ mm | D19: 1437.0418 | E19: 848.25439 | F19: 853.92355 | G19: 489.89565 | H19: 557.85819 | I19: 426.37281 | J19: 211.90273 | K19: 344.78036 | L19: 189.55061 | M19: 87.248808 | N19: 37.504676 | O19: -21.380932 | P19: =SUM(D19:O19) -> 5462.9526
B20: Discounted FCF - Expansion | C20: US$ mm | D20: 1640.9173 | E20: 972.02203 | F20: 977.57603 | G20: 565.18453 | H20: 641.07228 | I20: 479.71274 | J20: 241.14705 | K20: 388.22742 | L20: 215.58404 | M20: 101.60124 | N20: 46.104519 | O20: -13.669923 | P20: =SUM(D20:O20) -> 6255.4793 | Q20: =P20/P19-1 -> 0.14507295
B21: Incremental Uplift | C21: US$ mm | D21: =D20-D19 -> 203.87554 | E21: =E20-E19 -> 123.76763 | F21: =F20-F19 -> 123.65248 | G21: =G20-G19 -> 75.288888 | H21: =H20-H19 -> 83.214086 | I21: =I20-I19 -> 53.33993 | J21: =J20-J19 -> 29.244323 | K21: =K20-K19 -> 43.44706 | ... O21: =O20-O19 -> 7.7110089 | P21: =SUM(D21:O21) -> 792.52666 | Q21: =P21/P19 -> 0.14507295
B22: % Change | D22: =D21/D19 -> 0.14187169 | E22: =E21/E19 -> 0.14590863 | F22: =F21/F19 -> 0.1448051 | G22: =G21/G19 -> 0.15368352 | H22: =H21/H19 -> 0.1491671 | I22: =I21/I19 -> 0.12510162 | J22: =J21/J19 -> 0.13800824 | K22: =K21/K19 -> 0.12601373 | ... O22: =O21/O19 -> -0.36064887
B27: SUPPORTING GRAPHS
B28: Base Model | D28: =D7 -> 394939.48 | E28: =E7 -> 273095.31 | F28: =F7 -> 312215.67 | G28: =G7 -> 288199.08 | H28: =H7 -> 312215.67 | I28: =I7 -> 309093.51 | J28: =J7 -> 177455.91 | K28: =K7 -> 242834.41 | ... O28: =O7 -> 67673.413
B29: Incremental Uplift | D29: =D9 -> 52372.068 | E29: =E9 -> 35613.006 | F29: =F9 -> 40850.213 | G29: =G9 -> 37707.889 | H29: =H9 -> 40850.213 | I29: =I9 -> 34565.565 | J29: =J9 -> 19901.386 | K29: =K9 -> 27233.475 | ... O29: =O9 -> 8379.5308
B42: EXPANSION THESIS — TECHNICAL JUSTIFICATION
B43: Cutoff Grade Re-Rating & M&I Conversion Analysis at Spot Commodity Prices
B44: Source: Eskay Creek NI 43-101 Updated Feasibility Study, December 22, 2023
B46: CUTOFF GRADE RE-RATING ANALYSIS
B47: Parameter | C47: Units | D47: DFS Assumptions | E47: Model Base Case | F47: Δ Change
B48: Gold Price | C48: US$/oz | D48: 1700 | E48: ='Economic Assumptions'!I10 -> 3150 | F48: =(E48-D48)/D48 -> 0.85294118
B49: Silver Price | C49: US$/oz | D49: 23 | E49: ='Economic Assumptions'!I17 -> 42 | F49: =(E49-D49)/D49 -> 0.82608696
B50: Gold Recovery | C50: % | D50: 0.84 | E50: 0.84 | F50: —
B51: Silver Recovery | C51: % | D51: 0.88 | E51: 0.88 | F51: —
B52: Resource Cutoff Grade | C52: g/t AuEq | D52: 0.7 | E52: =D52*(D48/E48) -> 0.37777778 | F52: =(E52-D52)/D52 -> -0.46031746
B53: Reserve NSR Cutoff | C53: C$/t | D53: 24.45 | E53: =D53*((D48*D50)+(D49*D51))/((E48*E50)+(E49*E51)) -> 13.197911 | F53: =(E53-D53)/D53 -> -0.46020813
B55: ="AuEq Formula: AuEq = ((Au × $"&TEXT(D48,"#,##0")&" × "&TEXT(D50,"0.00")&") + (Ag × $"&TEXT(D49,"#,##0")&" × "&TEXT(D51,"0.00")&")) / ($"&TEXT(D48,"#,##0")&" × "&TEXT(D50,"0.00")&")" -> AuEq Formula: AuEq = ((Au × $1,700 × 0.84) + (Ag × $23 × 0.88)) / ($1,700 × 0.84)
B56: ="NSR Cut-off: C$"&TEXT(D53,"#,##0.00")&"/t based on processing costs of C$18.22/t + G&A of C$6.23/t" -> NSR Cut-off: C$24.45/t based on processing costs of C$18.22/t + G&A of C$6.23/t
B58: MINERAL RESOURCES & RESERVES — DFS TABLES (NI 43-101)
B60: Table 1-1: Mineral Resources — Open Pit (cutoff: 0.7 g/t AuEq)
B61: Category | C61: Tonnes (000) | D61: AuEq (g/t) | E61: Au (g/t) | F61: Ag (g/t) | G61: AuEq koz | H61: Au koz | I61: Ag koz
B62: Measured | C62: 27814 | D62: 4.6 | E62: 3.3 | F62: 87.9 | G62: 4077 | H62: 2964 | I62: 78560
B63: Indicated | C63: 22264 | D63: 2.1 | E63: 1.6 | F63: 32 | G63: 1468 | H63: 1144 | I63: 22876
...

Sheet Mine Overview
A4: Gold:Silver price ratio | B4: ='Economic Assumptions'!C7/'Economic Assumptions'!C8 -> 75
B6: Units | C6: ='NAV Model'!F56 -> 2027 | D6: ='NAV Model'!G56 -> 2028 | E6: ='NAV Model'!H56 -> 2029 | F6: ='NAV Model'!I56 -> 2030 | G6: ='NAV Model'!J56 -> 2031 | H6: ='NAV Model'!K56 -> 2032 | I6: ='NAV Model'!L56 -> 2033 | J6: ='NAV Model'!M56 -> 2034 | ... N6: ='NAV Model'!Q56 -> 2038
A8: AISC (US$/oz AuEq) | B8: US$/oz | C8: ='NAV Model'!F90 -> 602.60928 | D8: ='NAV Model'!G90 -> 825.31359 | E8: ='NAV Model'!H90 -> 724.7713 | F8: ='NAV Model'!I90 -> 751.48141 | G8: ='NAV Model'!J90 -> 698.5213 | H8: ='NAV Model'!K90 -> 506.83894 | I8: ='NAV Model'!L90 -> 834.42631 | J8: ='NAV Model'!M90 -> 626.73461 | ... N8: ='NAV Model'!Q90 -> 1942.7062
A10: Au Produced | B10: oz | C10: ='NAV Model'!F62 -> 394939.48 | D10: ='NAV Model'!G62 -> 273095.31 | E10: ='NAV Model'!H62 -> 312215.67 | F10: ='NAV Model'!I62 -> 288199.08 | G10: ='NAV Model'!J62 -> 312215.67 | H10: ='NAV Model'!K62 -> 309093.51 | I10: ='NAV Model'!L62 -> 177455.91 | J10: ='NAV Model'!M62 -> 242834.41 | ... N10: ='NAV Model'!Q62 -> 67673.413
A11: Ag Produced | B11: oz | C11: ='NAV Model'!F65 -> 7915348.4 | D11: ='NAV Model'!G65 -> 7573507.8 | E11: ='NAV Model'!H65 -> 10111274 | F11: ='NAV Model'!I65 -> 8891250.2 | G11: ='NAV Model'!J65 -> 12955069 | H11: ='NAV Model'!K65 -> 6469635.3 | I11: ='NAV Model'!L65 -> 4188162.1 | J11: ='NAV Model'!M65 -> 9789444.9 | ... N11: ='NAV Model'!Q65 -> 1057295.2
A12: AuEq Ag Produced | B12: oz | C12: =C11/$B$4 -> 105537.98 | D12: =D11/$B$4 -> 100980.1 | E12: =E11/$B$4 -> 134816.98 | F12: =F11/$B$4 -> 118550 | G12: =G11/$B$4 -> 172734.26 | H12: =H11/$B$4 -> 86261.803 | I12: =I11/$B$4 -> 55842.161 | J12: =J11/$B$4 -> 130525.93 | ... N12: =N11/$B$4 -> 14097.269
A13: Annual Production (koz AuEq) | B13: koz | C13: =SUM(C12,C10)/1000 -> 500.47746 | D13: =SUM(D12,D10)/1000 -> 374.07541 | E13: =SUM(E12,E10)/1000 -> 447.03265 | F13: =SUM(F12,F10)/1000 -> 406.74908 | G13: =SUM(G12,G10)/1000 -> 484.94993 | H13: =SUM(H12,H10)/1000 -> 395.35531 | I13: =SUM(I12,I10)/1000 -> 233.29807 | J13: =SUM(J12,J10)/1000 -> 373.36034 | ... N13: =SUM(N12,N10)/1000 -> 81.770682
A15: Total Opex (US$ mm) | C15: =C6 -> 2027 | D15: =D6 -> 2028 | E15: =E6 -> 2029 | F15: =F6 -> 2030 | G15: =G6 -> 2031 | H15: =H6 -> 2032 | I15: =I6 -> 2033 | J15: =J6 -> 2034 | ... N15: =N6 -> 2038
A16: Total Opex (US$ mm) | B16: ='NAV Model'!C81 -> US$ mm | C16: ='NAV Model'!F81-'NAV Model'!F79 -> 1132.2133 | D16: ='NAV Model'!G81-'NAV Model'!G79 -> 1475.1338 | E16: ='NAV Model'!H81-'NAV Model'!H79 -> 1389.3621 | F16: ='NAV Model'!I81-'NAV Model'!I79 -> 1086.5898 | G16: ='NAV Model'!J81-'NAV Model'!J79 -> 1362.9114 | H16: ='NAV Model'!K81-'NAV Model'!K79 -> 710.42258 | I16: ='NAV Model'!L81-'NAV Model'!L79 -> 918.09696 | J16: ='NAV Model'!M81-'NAV Model'!M79 -> 1384.7518 | ... N16: ='NAV Model'!Q81-'NAV Model'!Q79 -> 704.84415
A17: Total Capex (US$mm) | B17: ='NAV Model'!C88 -> US$ mm | C17: ='NAV Model'!F88 -> 34.142336 | D17: ='NAV Model'!G88 -> 34.142336 | E17: ='NAV Model'!H88 -> 34.142336 | F17: ='NAV Model'!I88 -> 34.142336 | G17: ='NAV Model'!J88 -> 34.142336 | H17: ='NAV Model'!K88 -> 40.492701 | I17: ='NAV Model'!L88 -> 34.142336 | J17: ='NAV Model'!M88 -> 34.142336 | ... N17: ='NAV Model'!Q88 -> 161.73358

Sheet Data Inputs ->

Sheet Reserve & Resource
A1: MINERAL RESERVE & RESOURCE STATEMENT
A2: Source: Technical Report, Section 14-15
A4: Category | B4: Tonnes (000) | C4: AuEq (g/t) | D4: Au (g/t) | E4: Ag (g/t) | F4: AuEq Oz (000) | G4: Au Oz (000) | H4: Ag Oz (000)
A5: Measured | B5: 27814 | C5: 4.6 | D5: 3.3 | E5: 87.9 | F5: 4077 | G5: 2964 | H5: 78560
A6: Indicated | B6: 22264 | C6: 2.1 | D6: 1.6 | E6: 32 | F6: 1468 | G6: 1144 | H6: 22876
A7: Total Measured + Indicated | B7: 50078 | C7: 3.4 | D7: 2.6 | E7: 63 | F7: 5545 | G7: 4107 | H7: 101436
A8: Inferred | B8: 652 | C8: 1.9 | D8: 1.5 | E8: 32.4 | F8: 40 | G8: 30 | H8: 680
A11: MINERAL RESERVE STATEMENT
A13: Category | B13: Tonnes (000) | C13: AuEq (g/t) | D13: Au (g/t) | E13: Ag (g/t) | F13: AuEq Oz (000) | G13: Au Oz (000) | H13: Ag Oz (000)
A14: Proven | B14: 27954 | C14: 4.1 | D14: 3 | E14: 80.9 | F14: 3675 | G14: 2657 | H14: 72661
A15: Probable | B15: 11889 | C15: 2.3 | D15: 1.8 | E15: 40.1 | F15: 894 | G15: 680 | H15: 15308
A16: Total Proven + Probable | B16: 39843 | C16: 3.6 | D16: 2.6 | E16: 68.7 | F16: 4569 | G16: 3336 | H16: 87969
A18: EXPANSION SCENARIO — M&I CONVERSION
E19: Conversion % | F19: ='Thesis 2'!D89 -> 0.094057874
A20: Category | B20: Tonnes (000) | C20: AuEq (g/t) | D20: AuEq Oz (000)
A21: Total M&I Resources (OP) | B21: =B7 -> 50078 | C21: =C7 -> 3.4 | D21: =F7 -> 5545
A22: ="Cutoff-Implied Conversion ("&TEXT(F19,"0.0%")&")" -> Cutoff-Implied Conversion (9.4%) | B22: =B21*F19 -> 4710.2302 | C22: =C21 -> 3.4 | D22: =D21*F19 -> 521.55091
A24: Existing P&P Reserves | B24: =B16 -> 39843 | C24: =C16 -> 3.6 | D24: =F16 -> 4569
A25: (+) Converted M&I | B25: =B22 -> 4710.2302 | C25: =C22 -> 3.4 | D25: =D22 -> 521.55091
A27: New P&P Total | B27: =B24+B25 -> 44553.23 | D27: =D24+D25 -> 5090.5509

Sheet Production Schedule
A1: LIFE OF MINE PRODUCTION SCHEDULE
A2: Source: Eskay Creek NI 43-101 Updated Feasibility Study, Table 16-3, December 22, 2023
A4: MINING SUMMARY
A5: Description | B5: Units | C5: Y-3 | D5: Y-2 | E5: Y-1 | F5: Y1 | G5: Y2 | H5: Y3 | I5: Y4 | J5: Y5 | K5: Y6 | L5: Y7 | M5: Y8 | N5: Y9 | O5: Y10 | P5: Y11 | Q5: Y12 | R5: Total
A6: NAG Waste | B6: Mt | C6: 1.62 | D6: 6.29 | E6: 9.26 | F6: 24.97 | G6: 21.31 | H6: 26.01 | I6: 21.29 | J6: 20.36 | K6: 10.03 | L6: 11.9 | M6: 11.48 | N6: 1.99 | O6: 0 | P6: 0 | Q6: 0 | R6: 166.5
A7: PAG Waste | B7: Mt | C7: 0.33 | D7: 2.27 | E7: 8.01 | F7: 15.26 | G7: 18.07 | H7: 20.01 | I7: 18.81 | J7: 17.93 | K7: 22.29 | L7: 8.84 | M7: 9.7 | N7: 9.85 | O7: 0 | P7: 0 | Q7: 0 | R7: 151.39
A8: Mined Waste | B8: Mt | C8: 1.95 | D8: 8.57 | E8: 17.27 | F8: 40.23 | G8: 39.38 | H8: 46.03 | I8: 40.1 | J8: 38.29 | K8: 32.32 | L8: 20.74 | M8: 21.18 | N8: 11.85 | O8: 0 | P8: 0 | Q8: 0 | R8: 317.89
A9: Mined Ore | B9: Mt | C9: 0 | D9: 0.06 | E9: 1.49 | F9: 5.69 | G9: 4.74 | H9: 3.93 | I9: 4.79 | J9: 5.21 | K9: 5.02 | L9: 1.38 | M9: 3.47 | N9: 4.06 | O9: 0 | P9: 0 | Q9: 0 | R9: 39.84
A10: Au Grade | B10: g/t | C10: 0 | D10: 4.2 | E10: 1.7 | F10: 3 | G10: 2.5 | H10: 3.3 | I10: 2.7 | J10: 2.7 | K10: 2.6 | L10: 2.8 | M10: 2.6 | N10: 1.5 | O10: 0 | P10: 0 | Q10: 0 | R10: 2.6
A11: Ag Grade | B11: g/t | C11: 0 | D11: 28.5 | E11: 48.6 | F11: 57.5 | G11: 58.6 | H11: 93.9 | I11: 71.4 | J11: 92.2 | K11: 46 | L11: 66.3 | M11: 93.6 | N11: 53.9 | O11: 0 | P11: 0 | Q11: 0 | R11: 68.7
A12: Total Mined | B12: Mt | C12: 1.95 | D12: 8.63 | E12: 18.77 | F12: 45.92 | G12: 44.12 | H12: 49.96 | I12: 44.89 | J12: 43.5 | K12: 37.34 | L12: 22.12 | M12: 24.65 | N12: 15.9 | O12: 0 | P12: 0 | Q12: 0 | R12: 357.73
A14: PROCESSED MATERIAL (MILL FEED)
A15: Mill Feed | B15: Mt | C15: 0 | D15: 0 | E15: 0.68 | F15: 2.96 | G15: 3.01 | H15: 3 | I15: 3 | J15: 3 | K15: 3.51 | L15: 3.5 | M15: 3.5 | N15: 3.5 | O15: 3.51 | P15: 3.5 | Q15: 3.17 | R15: 39.84
A16: Au Grade | B16: g/t | C16: 0 | D16: 0 | E16: 2 | F16: 5 | G16: 3.4 | H16: 3.9 | I16: 3.6 | J16: 3.9 | K16: 3.3 | L16: 1.9 | M16: 2.6 | N16: 1.7 | O16: 1.2 | P16: 0.8 | Q16: 0.8 | R16: 2.6
A17: Ag Grade | B17: g/t | C17: 0 | D17: 0 | E17: 53.4 | F17: 91.4 | G17: 86 | H17: 115.2 | I17: 101.3 | J17: 147.6 | K17: 63 | L17: 40.9 | M17: 95.6 | N17: 60.7 | O17: 23.6 | P17: 13.7 | Q17: 11.4 | R17: 68.7
A19: STOCKPILE & MATERIAL MOVEMENT
A20: Medium Grade | B20: Mt | C20: 0 | D20: 0.06 | E20: 1.25 | F20: 2.44 | G20: 1.34 | H20: 1.59 | I20: 1.62 | J20: 1.55 | K20: 0.81 | L20: 0.37 | M20: 0.35 | N20: 0.28 | O20: 0 | P20: 0 | Q20: 0
A21: Low Grade | B21: Mt | C21: 0 | D21: 0 | E21: 0.25 | F21: 0.98 | G21: 0.84 | H21: 0.51 | I21: 0.52 | J21: 0.67 | K21: 0.86 | L21: 0.16 | M21: 0.6 | N21: 0.65 | O21: 0 | P21: 0 | Q21: 0
A22: Total Stockpile Balance | B22: Mt | C22: 0 | D22: 0.06 | E22: 1.49 | F22: 3.41 | G22: 2.18 | H22: 2.1 | I22: 2.14 | J22: 2.21 | K22: 1.67 | L22: 0.53 | M22: 0.96 | N22: 0.93 | O22: 0 | P22: 0 | Q22: 0 | R22: 17.68
A23: Total Stockpile Reclaim | B23: Mt | C23: 0 | D23: 0 | E23: 0.68 | F23: 0.69 | G23: 0.45 | H23: 1.17 | I23: 0.35 | J23: 0 | K23: 0.16 | L23: 2.64 | M23: 0.98 | N23: 0.37 | O23: 3.51 | P23: 3.5 | Q23: 3.17 | R23: 17.68
A24: Total Material Movement | B24: Mt | C24: 1.95 | D24: 8.63 | E24: 19.45 | F24: 46.61 | G24: 44.56 | H24: 51.13 | I24: 45.24 | J24: 43.5 | K24: 37.5 | L24: 24.77 | M24: 25.63 | N24: 16.28 | O24: 3.51 | P24: 3.5 | Q24: 3.17 | R24: 375.41

Sheet Operating Costs
A1: OPERATING COST ESTIMATES
A2: Paste the LOM operating cost breakdown from the technical report below (Section 21)
B4: Initial (Years 1–5) | D4: Expansion (Year 6+) | F4: LOM Total
A5: Cost Category | B5: C$M | C5: C$/t milled | D5: C$M/a | E5: C$/t milled | F5: C$M | G5: C$/t milled
A6: Mining | B6: 710.5 | C6: 45.4 | D6: 347 | E6: 14.34 | F6: 1057.5 | G6: 26.54
A7: Processing | B7: 313.5 | C7: 20.03 | D7: 450 | E7: 18.6 | F7: 763.5 | G7: 19.16
A8: G&A | B8: 150.1 | C8: 9.59 | D8: 176.1 | E8: 7.28 | F8: 326.2 | G8: 8.19
A9: Total | B9: 1174.2 | C9: 75.03 | D9: 973.1 | E9: 40.22 | F9: 2147.3 | G9: 53.89
A11: Note: Costs are in C$/t milled from the technical report. Convert to USD/oz for the NAV model using the FX rate and production schedule.

Sheet Concentrate Overview
A1: CONCENTRATE GRADE SUMMARY
A2: Annual & Life-of-Mine Payable / Deleterious Element Grades
A4: Status | B4: Element | C4: Unit | D4: Minimum (Annual) | E4: Maximum (Annual) | F4: Average (LOM)
A5: Payable | B5: Au | C5: g/t | D5: 17 | E5: 94 | F5: 55
B6: Ag | C6: g/t | D6: 283 | E6: 2943 | F6: 1588
B7: Pb | C7: % | D7: 2.19 | E7: 13.93 | F7: 8.06
B8: Zn | C8: % | D8: 4.02 | E8: 21.03 | F8: 12.79
B9: Cu | C9: % | D9: 0.48 | E9: 2.05 | F9: 1.14
A10: Deleterious | B10: As | C10: % | D10: 0.69 | E10: 5.96 | F10: 1.5
B11: Hg | C11: % | D11: 0.03 | E11: 0.32 | F11: 0.08
A12: Payable / Deleterious | B12: Sb | C12: % | D12: 0.74 | E12: 5.72 | F12: 1.78

Sheet Capital Costs
A1: CAPITAL COST ESTIMATES
A2: Paste the capex schedule from the technical report below (Section 21)
A4: Description | B4: Initial (C$M) | C4: Sustaining (C$M) | D4: Expansion (C$M) | E4: Closure (C$M)
A5: Mining | B5: 113.7 | C5: 426 | D5: — | E5: —
A6: Ore Crushing and Reclaim | B6: 38 | C6: 3 | D6: — | E6: —
A7: Process Plant | B7: 171.8 | C7: 2 | D7: 8 | E7: —
A8: Tailings Reclaim and Water Treatment | B8: 21.7 | C8: 65.3 | D8: — | E8: —
A9: On-Site Infrastructure | B9: 98.6 | C9: 52 | D9: — | E9: —
A10: Off-Site Infrastructure | B10: 30.3 | C10: — | D10: — | E10: —
A11: Owner's Costs | B11: 92.6 | C11: — | D11: — | E11: —
A12: Indirect Costs | B12: 97.5 | C12: 13 | D12: 0.7 | E12: —
A13: Subtotal | B13: 664.2 | C13: 561.3 | D13: 8.7 | E13: —
A14: Contingency | B14: 48.7 | C14: — | D14: — | E14: —
A15: Closure | B15: — | C15: — | D15: — | E15: 174.8
A16: Total | B16: 712.9 | C16: 561.3 | D16: 8.7 | E16: 174.8

Sheet Financial Statements ->

Sheet Statement of Loss
A1: CONSOLIDATED STATEMENTS OF LOSS AND COMPREHENSIVE LOSS
A2: Source: Skeena Gold & Silver, Years ended December 31
A3: (expressed in thousands of Canadian dollars, except per share amounts)
B5: 2024 | C5: 2023
A6: Accretion | B6: 1013 | C6: 339
A7: Administrative compensation | B7: 5892 | C7: 6378
A8: Change in FV of convertible debenture | B8: 3153 | C8: 164
A9: Change in FV of derivative liability | B9: -7737 | C9: 0
A10: Communications | B10: 1579 | C10: 1316
A11: Consulting | B11: 4231 | C11: 1140
A12: Depreciation | B12: 859 | C12: 392
A13: Exploration and evaluation | B13: 146922 | C13: 91855
A14: Flow-through share premium recovery | B14: -17429 | C14: -5078
A15: Interest income | B15: -3694 | C15: -2040
A16: Share-based payments | B16: 8799 | C16: 8856
A17: Other expenses (net) | B17: 8351 | C17: 5302
... A23: Wtd avg shares outstanding | B23: 99128496 | C23: 84353282

Sheet Balance Sheet
A1: CONSOLIDATED STATEMENTS OF FINANCIAL POSITION
A2: Source: Skeena Gold & Silver
A3: (expressed in thousands of Canadian dollars)
B5: 45657 | C5: 45291
A6: ASSETS
A7: Cash and cash equivalents | B7: 96941 | C7: 91135
A8: Marketable securities | B8: 949 | C8: 1554
A9: Receivables | B9: 2351 | C9: 3225
A10: Other current assets | B10: 698 | C10: 1588
A11: Total current assets | B11: 100939 | C11: 97502
A12: Deposits | B12: 5083 | C12: 2102
A13: Exploration and evaluation interests | B13: 18662 | C13: 62414
A14: Mineral property, plant and equipment | B14: 144220 | C14: 32969
A15: Other non-current assets | B15: 5487 | C15: 0
A16: Total assets | B16: 274391 | C16: 194987
A18: LIABILITIES
A19: Accounts payable and accrued liabilities | B19: 57285 | C19: 20588
A20: Current portion of lease liabilities | B20: 6303 | C20: 1061
A21: Flow-through share premium liability | B21: 5708 | C21: 3137
A22: Other current liabilities | B22: 721 | C22: 449
A23: Total current liabilities | B23: 70017 | C23: 25235
A24: Lease liabilities (non-current) | B24: 7230 | C24: 8546
A25: Derivative liability (Gold Stream) | B25: 63886 | C25: 0
A26: Provision for closure and reclamation | B26: 38499 | C26: 13654
A27: Other non-current liabilities | B27: 4146 | C27: 242
A28: Total liabilities | B28: 183778 | C28: 70452
A30: SHAREHOLDERS' EQUITY
A31: Capital stock | B31: 670126 | C31: 552397
A32: Commitment to issue shares | B32: 250 | C32: 750
A33: Reserves | B33: 47346 | C33: 48299
A34: Deficit | B34: -627109 | C34: -476911
A35: Total shareholders' equity | B35: 90613 | C35: 124535
A36: Total liabilities and equity | B36: 274391 | C36: 194987

Sheet Cash Flow Statement
A1: CASH FLOW STATEMENT
A2: Source: Skeena Gold & Silver, Annual Financial Statements, Years ended December 31
A3: (expressed in thousands of Canadian dollars)
B5: 2024 | C5: 2023
A6: OPERATING ACTIVITIES
A7: Loss for the year | B7: -151939 | C7: -108980
A8: Accretion | B8: 1608 | C8: 546
A9: Change in FV of convertible debenture | B9: 3153 | C9: 164
A10: Change in FV of derivative liability | B10: -7737 | C10: 0
A11: Depreciation | B11: 8223 | C11: 2400
A12: E&E expenses capitalized | B12: -857 | C12: 0
A13: Flow-through share premium recovery | B13: -17429 | C13: -5078
A14: Share-based payments | B14: 13126 | C14: 11987
A15: Other non-cash items | B15: -2878 | C15: -22
A16: Changes in working capital | B16: 22846 | C16: 8351
A17: Net cash used in operating activities | B17: -127900 | C17: -90598
A19: INVESTING ACTIVITIES
A20: Proceeds from sale of marketable securities | B20: 38 | C20: 396
A21: Deposits paid | B21: -12469 | C21: -125
A22: Exploration and evaluation expenditures | B22: -8799 | C22: -14354
A23: Net proceeds from sale of NSR | B23: 0 | C23: 56000
A24: Additions to mineral property, PP&E | B24: -2213 | C24: -8749
A25: Other investing activities | B25: -387 | C25: -1900
A26: Net cash provided by (used in) investing | B26: -23830 | C26: 31268
A28: FINANCING ACTIVITIES
A29: Lease payments | B29: -8582 | C29: -991
A30: Repayment of convertible debenture | B30: -25928 | C30: 0
A31: Proceeds from Gold Stream | B31: 71623 | C31: 0
A32: Equity proceeds (placements, options, warrants) | B32: 125633 | C32: 89911
A33: Share issue costs & other | B33: -5975 | C33: -4057
A34: Net cash provided by financing | B34: 156771 | C34: 109863
A36: Effect of FX on cash | B36: 765 | C36: 0
A37: Change in cash during the year | B37: 5806 | C37: 50533
A39: Cash, beginning of year | B39: 91135 | C39: 40602
A40: Cash, end of year | B40: 96941 | C40: 91135
